hi
Wed 22 Mar 17:38:13 GMT 2023
compute-permanent-node-269
uid=10025(asa_cooper_stickland) gid=10012(owain_evans) groups=10012(owain_evans)
/data/asa_cooper_stickland/situational-awareness
doing it in one go
1
wandb: Currently logged in as: asacoopstick. Use `wandb login --relogin` to force relogin
wandb: wandb version 0.14.0 is available!  To upgrade, please run:
wandb:  $ pip install wandb --upgrade
wandb: Tracking run with wandb version 0.13.10
wandb: Run data is saved locally in /data/asa_cooper_stickland/situational-awareness/wandb/run-20230322_173841-y2i8wvt4
wandb: Run `wandb offline` to turn off syncing.
wandb: Syncing run asa_reward_test (40282_0)
wandb: ‚≠êÔ∏è View project at https://wandb.ai/asacoopstick/opensource-flan-t5
wandb: üöÄ View run at https://wandb.ai/asacoopstick/opensource-flan-t5/runs/y2i8wvt4
Loading model
Loading tokenizer and generating datasets
Failed to generate datasets, retrying
Failed to generate datasets, retrying
Failed to generate datasets, retrying
wandb: Waiting for W&B process to finish... (failed 1). Press Control-C to abort syncing.
wandb: üöÄ View run asa_reward_test (40282_0) at: https://wandb.ai/asacoopstick/opensource-flan-t5/runs/y2i8wvt4
wandb: Synced 6 W&B file(s), 0 media file(s), 2 artifact file(s) and 0 other file(s)
wandb: Find logs at: ./wandb/run-20230322_173841-y2i8wvt4/logs
Traceback (most recent call last):
  File "/data/asa_cooper_stickland/situational-awareness/scripts/t5/train.py", line 581, in <module>
    train(project=args.project,
  File "/data/asa_cooper_stickland/situational-awareness/scripts/t5/train.py", line 450, in train
    raise e
  File "/data/asa_cooper_stickland/situational-awareness/scripts/t5/train.py", line 441, in train
    train_dataset, eval_dataset, prompt2subject = generate_datasets(
  File "/data/asa_cooper_stickland/situational-awareness/scripts/t5/generate_data.py", line 26, in generate_datasets
    dataset = load_dataset(
  File "/data/asa_cooper_stickland/anaconda3/envs/initial/lib/python3.8/site-packages/datasets/load.py", line 1759, in load_dataset
    builder_instance = load_dataset_builder(
  File "/data/asa_cooper_stickland/anaconda3/envs/initial/lib/python3.8/site-packages/datasets/load.py", line 1496, in load_dataset_builder
    dataset_module = dataset_module_factory(
  File "/data/asa_cooper_stickland/anaconda3/envs/initial/lib/python3.8/site-packages/datasets/load.py", line 1129, in dataset_module_factory
    return PackagedDatasetModuleFactory(
  File "/data/asa_cooper_stickland/anaconda3/envs/initial/lib/python3.8/site-packages/datasets/load.py", line 709, in get_module
    data_files = DataFilesDict.from_local_or_remote(
  File "/data/asa_cooper_stickland/anaconda3/envs/initial/lib/python3.8/site-packages/datasets/data_files.py", line 796, in from_local_or_remote
    DataFilesList.from_local_or_remote(
  File "/data/asa_cooper_stickland/anaconda3/envs/initial/lib/python3.8/site-packages/datasets/data_files.py", line 764, in from_local_or_remote
    data_files = resolve_patterns_locally_or_by_urls(base_path, patterns, allowed_extensions)
  File "/data/asa_cooper_stickland/anaconda3/envs/initial/lib/python3.8/site-packages/datasets/data_files.py", line 362, in resolve_patterns_locally_or_by_urls
    for path in _resolve_single_pattern_locally(base_path, pattern, allowed_extensions):
  File "/data/asa_cooper_stickland/anaconda3/envs/initial/lib/python3.8/site-packages/datasets/data_files.py", line 306, in _resolve_single_pattern_locally
    raise FileNotFoundError(error_msg)
FileNotFoundError: Unable to find '/data/max_kaufmann/situational-awareness/data/finetuning/online_questions/simple_completion_ug100_rg1000_1docgph10_all.jsonl' at /
